<?xml version="1.0"?>
<robot name="quadrotor">
  <!-- Base link (body) -->
  <link name="base_link">
    <inertial>
      <mass value="1.0" />
      <origin xyz="0 0 0" rpy="0 0 0" />
      <inertia ixx="0.01" ixy="0" ixz="0" iyy="0.01" iyz="0" izz="0.02" />
    </inertial>
    <visual>
      <origin xyz="0 0 0" rpy="0 0 0" />
      <geometry>
        <cylinder radius="0.1" length="0.05" />
      </geometry>
      <material name="blue">
        <color rgba="0.1 0.1 0.8 1.0" />
      </material>
    </visual>
    <collision>
      <origin xyz="0 0 0" rpy="0 0 0" />
      <geometry>
        <cylinder radius="0.1" length="0.05" />
      </geometry>
    </collision>
  </link>

  <!-- Arms -->
  <!-- Arm 1 (front) -->
  <link name="arm_1">
    <inertial>
      <mass value="0.1" />
      <origin xyz="0.075 0 0" rpy="0 0 0" />
      <inertia ixx="0.001" ixy="0" ixz="0" iyy="0.001" iyz="0" izz="0.001" />
    </inertial>
    <visual>
      <origin xyz="0.075 0 0" rpy="0 0 0" />
      <geometry>
        <box size="0.15 0.02 0.02" />
      </geometry>
      <material name="gray">
        <color rgba="0.5 0.5 0.5 1.0" />
      </material>
    </visual>
    <collision>
      <origin xyz="0.075 0 0" rpy="0 0 0" />
      <geometry>
        <box size="0.15 0.02 0.02" />
      </geometry>
    </collision>
  </link>

  <!-- Arm 2 (right) -->
  <link name="arm_2">
    <inertial>
      <mass value="0.1" />
      <origin xyz="0 0.075 0" rpy="0 0 0" />
      <inertia ixx="0.001" ixy="0" ixz="0" iyy="0.001" iyz="0" izz="0.001" />
    </inertial>
    <visual>
      <origin xyz="0 0.075 0" rpy="0 0 0" />
      <geometry>
        <box size="0.02 0.15 0.02" />
      </geometry>
      <material name="gray" />
    </visual>
    <collision>
      <origin xyz="0 0.075 0" rpy="0 0 0" />
      <geometry>
        <box size="0.02 0.15 0.02" />
      </geometry>
    </collision>
  </link>

  <!-- Arm 3 (back) -->
  <link name="arm_3">
    <inertial>
      <mass value="0.1" />
      <origin xyz="-0.075 0 0" rpy="0 0 0" />
      <inertia ixx="0.001" ixy="0" ixz="0" iyy="0.001" iyz="0" izz="0.001" />
    </inertial>
    <visual>
      <origin xyz="-0.075 0 0" rpy="0 0 0" />
      <geometry>
        <box size="0.15 0.02 0.02" />
      </geometry>
      <material name="gray" />
    </visual>
    <collision>
      <origin xyz="-0.075 0 0" rpy="0 0 0" />
      <geometry>
        <box size="0.15 0.02 0.02" />
      </geometry>
    </collision>
  </link>

  <!-- Arm 4 (left) -->
  <link name="arm_4">
    <inertial>
      <mass value="0.1" />
      <origin xyz="0 -0.075 0" rpy="0 0 0" />
      <inertia ixx="0.001" ixy="0" ixz="0" iyy="0.001" iyz="0" izz="0.001" />
    </inertial>
    <visual>
      <origin xyz="0 -0.075 0" rpy="0 0 0" />
      <geometry>
        <box size="0.02 0.15 0.02" />
      </geometry>
      <material name="gray" />
    </visual>
    <collision>
      <origin xyz="0 -0.075 0" rpy="0 0 0" />
      <geometry>
        <box size="0.02 0.15 0.02" />
      </geometry>
    </collision>
  </link>

  <!-- Propellers -->
  <!-- Propeller 1 (front) -->
  <link name="propeller_1">
    <inertial>
      <mass value="0.05" />
      <origin xyz="0 0 0" rpy="0 0 0" />
      <inertia ixx="0.0001" ixy="0" ixz="0" iyy="0.0001" iyz="0" izz="0.0002" />
    </inertial>
    <visual>
      <origin xyz="0 0 0" rpy="0 0 0" />
      <geometry>
        <cylinder radius="0.05" length="0.01" />
      </geometry>
      <material name="red">
        <color rgba="0.8 0.1 0.1 1.0" />
      </material>
    </visual>
    <collision>
      <origin xyz="0 0 0" rpy="0 0 0" />
      <geometry>
        <cylinder radius="0.05" length="0.01" />
      </geometry>
    </collision>
  </link>

  <!-- Propeller 2 (right) -->
  <link name="propeller_2">
    <inertial>
      <mass value="0.05" />
      <origin xyz="0 0 0" rpy="0 0 0" />
      <inertia ixx="0.0001" ixy="0" ixz="0" iyy="0.0001" iyz="0" izz="0.0002" />
    </inertial>
    <visual>
      <origin xyz="0 0 0" rpy="0 0 0" />
      <geometry>
        <cylinder radius="0.05" length="0.01" />
      </geometry>
      <material name="green">
        <color rgba="0.1 0.8 0.1 1.0" />
      </material>
    </visual>
    <collision>
      <origin xyz="0 0 0" rpy="0 0 0" />
      <geometry>
        <cylinder radius="0.05" length="0.01" />
      </geometry>
    </collision>
  </link>

  <!-- Propeller 3 (back) -->
  <link name="propeller_3">
    <inertial>
      <mass value="0.05" />
      <origin xyz="0 0 0" rpy="0 0 0" />
      <inertia ixx="0.0001" ixy="0" ixz="0" iyy="0.0001" iyz="0" izz="0.0002" />
    </inertial>
    <visual>
      <origin xyz="0 0 0" rpy="0 0 0" />
      <geometry>
        <cylinder radius="0.05" length="0.01" />
      </geometry>
      <material name="red" />
    </visual>
    <collision>
      <origin xyz="0 0 0" rpy="0 0 0" />
      <geometry>
        <cylinder radius="0.05" length="0.01" />
      </geometry>
    </collision>
  </link>

  <!-- Propeller 4 (left) -->
  <link name="propeller_4">
    <inertial>
      <mass value="0.05" />
      <origin xyz="0 0 0" rpy="0 0 0" />
      <inertia ixx="0.0001" ixy="0" ixz="0" iyy="0.0001" iyz="0" izz="0.0002" />
    </inertial>
    <visual>
      <origin xyz="0 0 0" rpy="0 0 0" />
      <geometry>
        <cylinder radius="0.05" length="0.01" />
      </geometry>
      <material name="green" />
    </visual>
    <collision>
      <origin xyz="0 0 0" rpy="0 0 0" />
      <geometry>
        <cylinder radius="0.05" length="0.01" />
      </geometry>
    </collision>
  </link>

  <!-- Joints -->
  <!-- Arm 1 joint -->
  <joint name="base_to_arm_1" type="fixed">
    <parent link="base_link" />
    <child link="arm_1" />
    <origin xyz="0 0 0" rpy="0 0 0" />
  </joint>

  <!-- Arm 2 joint -->
  <joint name="base_to_arm_2" type="fixed">
    <parent link="base_link" />
    <child link="arm_2" />
    <origin xyz="0 0 0" rpy="0 0 0" />
  </joint>

  <!-- Arm 3 joint -->
  <joint name="base_to_arm_3" type="fixed">
    <parent link="base_link" />
    <child link="arm_3" />
    <origin xyz="0 0 0" rpy="0 0 0" />
  </joint>

  <!-- Arm 4 joint -->
  <joint name="base_to_arm_4" type="fixed">
    <parent link="base_link" />
    <child link="arm_4" />
    <origin xyz="0 0 0" rpy="0 0 0" />
  </joint>

  <!-- Propeller 1 joint -->
  <joint name="arm_1_to_propeller_1" type="continuous">
    <parent link="arm_1" />
    <child link="propeller_1" />
    <origin xyz="0.15 0 0" rpy="0 0 0" />
    <axis xyz="0 0 1" />
  </joint>

  <!-- Propeller 2 joint -->
  <joint name="arm_2_to_propeller_2" type="continuous">
    <parent link="arm_2" />
    <child link="propeller_2" />
    <origin xyz="0 0.15 0" rpy="0 0 0" />
    <axis xyz="0 0 1" />
  </joint>

  <!-- Propeller 3 joint -->
  <joint name="arm_3_to_propeller_3" type="continuous">
    <parent link="arm_3" />
    <child link="propeller_3" />
    <origin xyz="-0.15 0 0" rpy="0 0 0" />
    <axis xyz="0 0 1" />
  </joint>

  <!-- Propeller 4 joint -->
  <joint name="arm_4_to_propeller_4" type="continuous">
    <parent link="arm_4" />
    <child link="propeller_4" />
    <origin xyz="0 -0.15 0" rpy="0 0 0" />
    <axis xyz="0 0 1" />
  </joint>

</robot> 